2018-03-08 23:12:27,604 ERROR: Exception on /login [GET] [in /home/seng/microblog/venv/lib/python3.5/site-packages/flask/app.py:1560]
Traceback (most recent call last):
  File "/home/seng/microblog/venv/lib/python3.5/site-packages/flask/app.py", line 1982, in wsgi_app
    response = self.full_dispatch_request()
  File "/home/seng/microblog/venv/lib/python3.5/site-packages/flask/app.py", line 1614, in full_dispatch_request
    rv = self.handle_user_exception(e)
  File "/home/seng/microblog/venv/lib/python3.5/site-packages/flask/app.py", line 1517, in handle_user_exception
    reraise(exc_type, exc_value, tb)
  File "/home/seng/microblog/venv/lib/python3.5/site-packages/flask/_compat.py", line 33, in reraise
    raise value
  File "/home/seng/microblog/venv/lib/python3.5/site-packages/flask/app.py", line 1612, in full_dispatch_request
    rv = self.dispatch_request()
  File "/home/seng/microblog/venv/lib/python3.5/site-packages/flask/app.py", line 1598, in dispatch_request
    return self.view_functions[rule.endpoint](**req.view_args)
  File "/home/seng/microblog/app/routes.py", line 34, in login
    if current_user.is_authenticated():
TypeError: 'bool' object is not callable
2018-03-08 23:12:32,196 ERROR: Exception on /index [GET] [in /home/seng/microblog/venv/lib/python3.5/site-packages/flask/app.py:1560]
Traceback (most recent call last):
  File "/home/seng/microblog/venv/lib/python3.5/site-packages/flask/app.py", line 1982, in wsgi_app
    response = self.full_dispatch_request()
  File "/home/seng/microblog/venv/lib/python3.5/site-packages/flask/app.py", line 1614, in full_dispatch_request
    rv = self.handle_user_exception(e)
  File "/home/seng/microblog/venv/lib/python3.5/site-packages/flask/app.py", line 1517, in handle_user_exception
    reraise(exc_type, exc_value, tb)
  File "/home/seng/microblog/venv/lib/python3.5/site-packages/flask/_compat.py", line 33, in reraise
    raise value
  File "/home/seng/microblog/venv/lib/python3.5/site-packages/flask/app.py", line 1612, in full_dispatch_request
    rv = self.dispatch_request()
  File "/home/seng/microblog/venv/lib/python3.5/site-packages/flask/app.py", line 1598, in dispatch_request
    return self.view_functions[rule.endpoint](**req.view_args)
  File "/home/seng/microblog/app/routes.py", line 16, in decorated_view
    if not current_user.is_authenticated():
TypeError: 'bool' object is not callable
2018-03-08 23:12:33,576 ERROR: Exception on /login [GET] [in /home/seng/microblog/venv/lib/python3.5/site-packages/flask/app.py:1560]
Traceback (most recent call last):
  File "/home/seng/microblog/venv/lib/python3.5/site-packages/flask/app.py", line 1982, in wsgi_app
    response = self.full_dispatch_request()
  File "/home/seng/microblog/venv/lib/python3.5/site-packages/flask/app.py", line 1614, in full_dispatch_request
    rv = self.handle_user_exception(e)
  File "/home/seng/microblog/venv/lib/python3.5/site-packages/flask/app.py", line 1517, in handle_user_exception
    reraise(exc_type, exc_value, tb)
  File "/home/seng/microblog/venv/lib/python3.5/site-packages/flask/_compat.py", line 33, in reraise
    raise value
  File "/home/seng/microblog/venv/lib/python3.5/site-packages/flask/app.py", line 1612, in full_dispatch_request
    rv = self.dispatch_request()
  File "/home/seng/microblog/venv/lib/python3.5/site-packages/flask/app.py", line 1598, in dispatch_request
    return self.view_functions[rule.endpoint](**req.view_args)
  File "/home/seng/microblog/app/routes.py", line 34, in login
    if current_user.is_authenticated():
TypeError: 'bool' object is not callable
2018-03-08 23:15:06,111 INFO: Microblog startup [in /home/seng/microblog/app/__init__.py:44]
2018-03-08 23:15:09,397 ERROR: Exception on /index [GET] [in /home/seng/microblog/venv/lib/python3.5/site-packages/flask/app.py:1560]
Traceback (most recent call last):
  File "/home/seng/microblog/venv/lib/python3.5/site-packages/flask/app.py", line 1982, in wsgi_app
    response = self.full_dispatch_request()
  File "/home/seng/microblog/venv/lib/python3.5/site-packages/flask/app.py", line 1614, in full_dispatch_request
    rv = self.handle_user_exception(e)
  File "/home/seng/microblog/venv/lib/python3.5/site-packages/flask/app.py", line 1517, in handle_user_exception
    reraise(exc_type, exc_value, tb)
  File "/home/seng/microblog/venv/lib/python3.5/site-packages/flask/_compat.py", line 33, in reraise
    raise value
  File "/home/seng/microblog/venv/lib/python3.5/site-packages/flask/app.py", line 1612, in full_dispatch_request
    rv = self.dispatch_request()
  File "/home/seng/microblog/venv/lib/python3.5/site-packages/flask/app.py", line 1598, in dispatch_request
    return self.view_functions[rule.endpoint](**req.view_args)
  File "/home/seng/microblog/app/routes.py", line 16, in decorated_view
    return current_app.login_manager.unauthorized()
NameError: name 'current_app' is not defined
2018-03-08 23:16:03,015 INFO: Microblog startup [in /home/seng/microblog/app/__init__.py:44]
2018-03-08 23:16:05,176 ERROR: Exception on /index [GET] [in /home/seng/microblog/venv/lib/python3.5/site-packages/flask/app.py:1560]
Traceback (most recent call last):
  File "/home/seng/microblog/venv/lib/python3.5/site-packages/flask/app.py", line 1982, in wsgi_app
    response = self.full_dispatch_request()
  File "/home/seng/microblog/venv/lib/python3.5/site-packages/flask/app.py", line 1614, in full_dispatch_request
    rv = self.handle_user_exception(e)
  File "/home/seng/microblog/venv/lib/python3.5/site-packages/flask/app.py", line 1517, in handle_user_exception
    reraise(exc_type, exc_value, tb)
  File "/home/seng/microblog/venv/lib/python3.5/site-packages/flask/_compat.py", line 33, in reraise
    raise value
  File "/home/seng/microblog/venv/lib/python3.5/site-packages/flask/app.py", line 1612, in full_dispatch_request
    rv = self.dispatch_request()
  File "/home/seng/microblog/venv/lib/python3.5/site-packages/flask/app.py", line 1598, in dispatch_request
    return self.view_functions[rule.endpoint](**req.view_args)
  File "/home/seng/microblog/app/routes.py", line 16, in decorated_view
    return current_app.login_manager.unauthorized()
NameError: name 'current_app' is not defined
2018-03-08 23:18:15,448 INFO: Microblog startup [in /home/seng/microblog/app/__init__.py:44]
2018-03-08 23:18:18,158 ERROR: Exception on /index [GET] [in /home/seng/microblog/venv/lib/python3.5/site-packages/flask/app.py:1560]
Traceback (most recent call last):
  File "/home/seng/microblog/venv/lib/python3.5/site-packages/flask/app.py", line 1982, in wsgi_app
    response = self.full_dispatch_request()
  File "/home/seng/microblog/venv/lib/python3.5/site-packages/flask/app.py", line 1614, in full_dispatch_request
    rv = self.handle_user_exception(e)
  File "/home/seng/microblog/venv/lib/python3.5/site-packages/flask/app.py", line 1517, in handle_user_exception
    reraise(exc_type, exc_value, tb)
  File "/home/seng/microblog/venv/lib/python3.5/site-packages/flask/_compat.py", line 33, in reraise
    raise value
  File "/home/seng/microblog/venv/lib/python3.5/site-packages/flask/app.py", line 1612, in full_dispatch_request
    rv = self.dispatch_request()
  File "/home/seng/microblog/venv/lib/python3.5/site-packages/flask/app.py", line 1598, in dispatch_request
    return self.view_functions[rule.endpoint](**req.view_args)
  File "/home/seng/microblog/app/routes.py", line 17, in decorated_view
    return login_manager.unauthorized()
NameError: name 'login_manager' is not defined
2018-03-08 23:27:18,923 INFO: Microblog startup [in /home/seng/microblog/app/__init__.py:44]
2018-03-08 23:27:20,599 ERROR: Exception on /index [GET] [in /home/seng/microblog/venv/lib/python3.5/site-packages/flask/app.py:1560]
Traceback (most recent call last):
  File "/home/seng/microblog/venv/lib/python3.5/site-packages/flask/app.py", line 1982, in wsgi_app
    response = self.full_dispatch_request()
  File "/home/seng/microblog/venv/lib/python3.5/site-packages/flask/app.py", line 1614, in full_dispatch_request
    rv = self.handle_user_exception(e)
  File "/home/seng/microblog/venv/lib/python3.5/site-packages/flask/app.py", line 1517, in handle_user_exception
    reraise(exc_type, exc_value, tb)
  File "/home/seng/microblog/venv/lib/python3.5/site-packages/flask/_compat.py", line 33, in reraise
    raise value
  File "/home/seng/microblog/venv/lib/python3.5/site-packages/flask/app.py", line 1612, in full_dispatch_request
    rv = self.dispatch_request()
  File "/home/seng/microblog/venv/lib/python3.5/site-packages/flask/app.py", line 1598, in dispatch_request
    return self.view_functions[rule.endpoint](**req.view_args)
  File "/home/seng/microblog/app/routes.py", line 17, in decorated_view
    return current_app.login_manager.unauthorized()
NameError: name 'current_app' is not defined
2018-03-08 23:27:21,975 ERROR: Exception on /index [GET] [in /home/seng/microblog/venv/lib/python3.5/site-packages/flask/app.py:1560]
Traceback (most recent call last):
  File "/home/seng/microblog/venv/lib/python3.5/site-packages/flask/app.py", line 1982, in wsgi_app
    response = self.full_dispatch_request()
  File "/home/seng/microblog/venv/lib/python3.5/site-packages/flask/app.py", line 1614, in full_dispatch_request
    rv = self.handle_user_exception(e)
  File "/home/seng/microblog/venv/lib/python3.5/site-packages/flask/app.py", line 1517, in handle_user_exception
    reraise(exc_type, exc_value, tb)
  File "/home/seng/microblog/venv/lib/python3.5/site-packages/flask/_compat.py", line 33, in reraise
    raise value
  File "/home/seng/microblog/venv/lib/python3.5/site-packages/flask/app.py", line 1612, in full_dispatch_request
    rv = self.dispatch_request()
  File "/home/seng/microblog/venv/lib/python3.5/site-packages/flask/app.py", line 1598, in dispatch_request
    return self.view_functions[rule.endpoint](**req.view_args)
  File "/home/seng/microblog/app/routes.py", line 17, in decorated_view
    return current_app.login_manager.unauthorized()
NameError: name 'current_app' is not defined
