2018-03-09 01:17:41,863 ERROR: Exception on /login [GET] [in /home/seng/microblog/venv/lib/python3.5/site-packages/flask/app.py:1560]
Traceback (most recent call last):
  File "/home/seng/microblog/venv/lib/python3.5/site-packages/flask/app.py", line 1982, in wsgi_app
    response = self.full_dispatch_request()
  File "/home/seng/microblog/venv/lib/python3.5/site-packages/flask/app.py", line 1614, in full_dispatch_request
    rv = self.handle_user_exception(e)
  File "/home/seng/microblog/venv/lib/python3.5/site-packages/flask/app.py", line 1517, in handle_user_exception
    reraise(exc_type, exc_value, tb)
  File "/home/seng/microblog/venv/lib/python3.5/site-packages/flask/_compat.py", line 33, in reraise
    raise value
  File "/home/seng/microblog/venv/lib/python3.5/site-packages/flask/app.py", line 1612, in full_dispatch_request
    rv = self.dispatch_request()
  File "/home/seng/microblog/venv/lib/python3.5/site-packages/flask/app.py", line 1598, in dispatch_request
    return self.view_functions[rule.endpoint](**req.view_args)
  File "/home/seng/microblog/app/routes.py", line 59, in login
    return render_template('login.html',title='Sign In', form = form)
  File "/home/seng/microblog/venv/lib/python3.5/site-packages/flask/templating.py", line 134, in render_template
    context, ctx.app)
  File "/home/seng/microblog/venv/lib/python3.5/site-packages/flask/templating.py", line 116, in _render
    rv = template.render(context)
  File "/home/seng/microblog/venv/lib/python3.5/site-packages/jinja2/environment.py", line 1008, in render
    return self.environment.handle_exception(exc_info, True)
  File "/home/seng/microblog/venv/lib/python3.5/site-packages/jinja2/environment.py", line 780, in handle_exception
    reraise(exc_type, exc_value, tb)
  File "/home/seng/microblog/venv/lib/python3.5/site-packages/jinja2/_compat.py", line 37, in reraise
    raise value.with_traceback(tb)
  File "/home/seng/microblog/app/templates/base.html", line 22, in template
    {% if current_user.is_authenticated & current_user.get_urole %}
  File "/home/seng/microblog/venv/lib/python3.5/site-packages/jinja2/environment.py", line 1005, in render
    return concat(self.root_render_func(self.new_context(vars)))
  File "/home/seng/microblog/app/templates/login.html", line 1, in top-level template code
    {% extends "base.html" %}
  File "/home/seng/microblog/venv/lib/python3.5/site-packages/jinja2/environment.py", line 780, in handle_exception
    reraise(exc_type, exc_value, tb)
  File "/home/seng/microblog/venv/lib/python3.5/site-packages/jinja2/_compat.py", line 37, in reraise
    raise value.with_traceback(tb)
  File "/home/seng/microblog/app/templates/base.html", line 22, in template
    {% if current_user.is_authenticated & current_user.get_urole %}
  File "/home/seng/microblog/venv/lib/python3.5/site-packages/jinja2/environment.py", line 497, in _parse
    return Parser(self, source, name, encode_filename(filename)).parse()
  File "/home/seng/microblog/venv/lib/python3.5/site-packages/jinja2/parser.py", line 901, in parse
    result = nodes.Template(self.subparse(), lineno=1)
  File "/home/seng/microblog/venv/lib/python3.5/site-packages/jinja2/parser.py", line 883, in subparse
    rv = self.parse_statement()
  File "/home/seng/microblog/venv/lib/python3.5/site-packages/jinja2/parser.py", line 130, in parse_statement
    return getattr(self, 'parse_' + self.stream.current.value)()
  File "/home/seng/microblog/venv/lib/python3.5/site-packages/jinja2/parser.py", line 211, in parse_if
    node.test = self.parse_tuple(with_condexpr=False)
  File "/home/seng/microblog/venv/lib/python3.5/site-packages/jinja2/parser.py", line 620, in parse_tuple
    args.append(parse())
  File "/home/seng/microblog/venv/lib/python3.5/site-packages/jinja2/parser.py", line 612, in <lambda>
    parse = lambda: self.parse_expression(with_condexpr=False)
  File "/home/seng/microblog/venv/lib/python3.5/site-packages/jinja2/parser.py", line 433, in parse_expression
    return self.parse_or()
  File "/home/seng/microblog/venv/lib/python3.5/site-packages/jinja2/parser.py", line 450, in parse_or
    left = self.parse_and()
  File "/home/seng/microblog/venv/lib/python3.5/site-packages/jinja2/parser.py", line 459, in parse_and
    left = self.parse_not()
  File "/home/seng/microblog/venv/lib/python3.5/site-packages/jinja2/parser.py", line 470, in parse_not
    return self.parse_compare()
  File "/home/seng/microblog/venv/lib/python3.5/site-packages/jinja2/parser.py", line 474, in parse_compare
    expr = self.parse_math1()
  File "/home/seng/microblog/venv/lib/python3.5/site-packages/jinja2/parser.py", line 496, in parse_math1
    left = self.parse_concat()
  File "/home/seng/microblog/venv/lib/python3.5/site-packages/jinja2/parser.py", line 507, in parse_concat
    args = [self.parse_math2()]
  File "/home/seng/microblog/venv/lib/python3.5/site-packages/jinja2/parser.py", line 517, in parse_math2
    left = self.parse_pow()
  File "/home/seng/microblog/venv/lib/python3.5/site-packages/jinja2/parser.py", line 528, in parse_pow
    left = self.parse_unary()
  File "/home/seng/microblog/venv/lib/python3.5/site-packages/jinja2/parser.py", line 547, in parse_unary
    node = self.parse_postfix(node)
  File "/home/seng/microblog/venv/lib/python3.5/site-packages/jinja2/parser.py", line 672, in parse_postfix
    node = self.parse_subscript(node)
  File "/home/seng/microblog/venv/lib/python3.5/site-packages/jinja2/parser.py", line 700, in parse_subscript
    next(self.stream)
  File "/home/seng/microblog/venv/lib/python3.5/site-packages/jinja2/lexer.py", line 359, in __next__
    self.current = next(self._iter)
  File "/home/seng/microblog/venv/lib/python3.5/site-packages/jinja2/lexer.py", line 562, in wrap
    for lineno, token, value in stream:
  File "/home/seng/microblog/venv/lib/python3.5/site-packages/jinja2/lexer.py", line 739, in tokeniter
    name, filename)
jinja2.exceptions.TemplateSyntaxError: unexpected char '&' at 1028
2018-03-09 01:18:37,959 INFO: Microblog startup [in /home/seng/microblog/app/__init__.py:44]
2018-03-09 01:18:51,184 ERROR: Exception on /complaints [GET] [in /home/seng/microblog/venv/lib/python3.5/site-packages/flask/app.py:1560]
Traceback (most recent call last):
  File "/home/seng/microblog/venv/lib/python3.5/site-packages/flask/app.py", line 1982, in wsgi_app
    response = self.full_dispatch_request()
  File "/home/seng/microblog/venv/lib/python3.5/site-packages/flask/app.py", line 1614, in full_dispatch_request
    rv = self.handle_user_exception(e)
  File "/home/seng/microblog/venv/lib/python3.5/site-packages/flask/app.py", line 1517, in handle_user_exception
    reraise(exc_type, exc_value, tb)
  File "/home/seng/microblog/venv/lib/python3.5/site-packages/flask/_compat.py", line 33, in reraise
    raise value
  File "/home/seng/microblog/venv/lib/python3.5/site-packages/flask/app.py", line 1612, in full_dispatch_request
    rv = self.dispatch_request()
  File "/home/seng/microblog/venv/lib/python3.5/site-packages/flask/app.py", line 1598, in dispatch_request
    return self.view_functions[rule.endpoint](**req.view_args)
  File "/home/seng/microblog/app/routes.py", line 20, in decorated_view
    return current_app.login_manager.unauthorized()
NameError: name 'current_app' is not defined
2018-03-09 01:18:52,944 ERROR: Exception on /payroll [GET] [in /home/seng/microblog/venv/lib/python3.5/site-packages/flask/app.py:1560]
Traceback (most recent call last):
  File "/home/seng/microblog/venv/lib/python3.5/site-packages/flask/app.py", line 1982, in wsgi_app
    response = self.full_dispatch_request()
  File "/home/seng/microblog/venv/lib/python3.5/site-packages/flask/app.py", line 1614, in full_dispatch_request
    rv = self.handle_user_exception(e)
  File "/home/seng/microblog/venv/lib/python3.5/site-packages/flask/app.py", line 1517, in handle_user_exception
    reraise(exc_type, exc_value, tb)
  File "/home/seng/microblog/venv/lib/python3.5/site-packages/flask/_compat.py", line 33, in reraise
    raise value
  File "/home/seng/microblog/venv/lib/python3.5/site-packages/flask/app.py", line 1612, in full_dispatch_request
    rv = self.dispatch_request()
  File "/home/seng/microblog/venv/lib/python3.5/site-packages/flask/app.py", line 1598, in dispatch_request
    return self.view_functions[rule.endpoint](**req.view_args)
  File "/home/seng/microblog/app/routes.py", line 20, in decorated_view
    return current_app.login_manager.unauthorized()
NameError: name 'current_app' is not defined
2018-03-09 01:18:55,803 ERROR: Exception on /complaints [GET] [in /home/seng/microblog/venv/lib/python3.5/site-packages/flask/app.py:1560]
Traceback (most recent call last):
  File "/home/seng/microblog/venv/lib/python3.5/site-packages/flask/app.py", line 1982, in wsgi_app
    response = self.full_dispatch_request()
  File "/home/seng/microblog/venv/lib/python3.5/site-packages/flask/app.py", line 1614, in full_dispatch_request
    rv = self.handle_user_exception(e)
  File "/home/seng/microblog/venv/lib/python3.5/site-packages/flask/app.py", line 1517, in handle_user_exception
    reraise(exc_type, exc_value, tb)
  File "/home/seng/microblog/venv/lib/python3.5/site-packages/flask/_compat.py", line 33, in reraise
    raise value
  File "/home/seng/microblog/venv/lib/python3.5/site-packages/flask/app.py", line 1612, in full_dispatch_request
    rv = self.dispatch_request()
  File "/home/seng/microblog/venv/lib/python3.5/site-packages/flask/app.py", line 1598, in dispatch_request
    return self.view_functions[rule.endpoint](**req.view_args)
  File "/home/seng/microblog/app/routes.py", line 20, in decorated_view
    return current_app.login_manager.unauthorized()
NameError: name 'current_app' is not defined
